Workbook

Sheet Data
A1: Date | B1: Open | C1: High | D1: Low | E1: Close | F1: Visa Inc. (V) | G1: Volume | J1: Date | K1: Open | L1: High | M1: Low | N1: Close | O1: The Coca-Cola Company (KO) | P1: Volume
A2: 46091 | B2: 315.43 | C2: 316.46 | D2: 311.47 | E2: 316.11 | F2: 316.11 | G2: 1827488 | J2: 46091 | K2: 77.47 | L2: 78.14 | M2: 77.1 | N2: 78.13 | O2: 78.13 | P2: 3061527
A3: 46090 | B3: 313.46 | C3: 316.4 | D3: 310.15 | E3: 315.97 | F3: 315.97 | G3: 8380700 | J3: 46090 | K3: 76.62 | L3: 78.07 | M3: 76.53 | N3: 77.8 | O3: 77.8 | P3: 18549800
A4: 46083 | B4: 315.5 | C4: 325.77 | D4: 312.3 | E4: 317.36 | F4: 317.36 | G4: 32114000 | J4: 46083 | K4: 81.25 | L4: 81.4 | M4: 76.35 | N4: 77.04 | O4: 77.04 | P4: 98380000
A5: 46076 | B5: 319.04 | C5: 320.52 | D5: 303.08 | E5: 320.14 | F5: 320.14 | G5: 50930800 | J5: 46076 | K5: 79.52 | L5: 82 | M5: 79.5 | N5: 81.56 | O5: 81.56 | P5: 93019800
A6: 46069 | B6: 314.41 | C6: 322.35 | D6: 314.41 | E6: 320.95 | F6: 320.95 | G6: 28482300 | J6: 46069 | K6: 78.99 | L6: 79.84 | M6: 78.59 | N6: 79.84 | O6: 79.84 | P6: 64664900
A7: 46063 | B7: 0.67 Dividend | J7: 46062 | K7: 78.67 | L7: 80.41 | M7: 76.01 | N7: 78.68 | O7: 78.68 | P7: 117668900
A8: 46062 | B8: 330.76 | C8: 332.82 | D8: 312.82 | E8: 314.08 | F8: 313.43 | G8: 43626000 | J8: 46055 | K8: 75.01 | L8: 79.2 | M8: 74.4 | N8: 79.03 | O8: 79.03 | P8: 115061800
A9: 46055 | B9: 324.83 | C9: 337.59 | D9: 324.11 | E9: 331.58 | F9: 330.9 | G9: 42193700 | J9: 46048 | K9: 72.86 | L9: 74.9 | M9: 72.27 | N9: 74.81 | O9: 74.81 | P9: 89172900
A10: 46048 | B10: 328 | C10: 333.36 | D10: 321.6 | E10: 321.83 | F10: 321.17 | G10: 43425300 | J10: 46041 | K10: 70 | L10: 73.06 | M10: 69.79 | N10: 72.88 | O10: 72.88 | P10: 76082700
A11: 46041 | B11: 322.23 | C11: 328.67 | D11: 321.56 | E11: 326.18 | F11: 325.51 | G11: 29861100 | J11: 46034 | K11: 70.9 | L11: 71.71 | M11: 70.04 | N11: 70.44 | O11: 70.44 | P11: 91138000
A12: 46034 | B12: 342.78 | C12: 346.51 | D12: 323.83 | E12: 328.3 | F12: 327.62 | G12: 59982500 | J12: 46027 | K12: 68.92 | L12: 70.66 | M12: 67.27 | N12: 70.51 | O12: 70.51 | P12: 101305500
A13: 46027 | B13: 344.5 | C13: 358.62 | D13: 344.05 | E13: 349.77 | F13: 349.05 | G13: 31962000 | J13: 46020 | K13: 70 | L13: 70.42 | M13: 68.98 | N13: 69.12 | O13: 69.12 | P13: 38576900
A14: 46020 | B14: 355.49 | C14: 356.55 | D14: 343.48 | E14: 346.48 | F14: 345.77 | G14: 16263400 | J14: 46013 | K14: 69.93 | L14: 70.26 | M14: 69.66 | N14: 69.87 | O14: 69.87 | P14: 32526200
A15: 46013 | B15: 350 | C15: 356.73 | D15: 349.59 | E15: 355 | F15: 354.27 | G15: 12787300 | J15: 46006 | K15: 70.43 | L15: 71.32 | M15: 70.03 | N15: 70.06 | O15: 70.06 | P15: 102138700
A16: 46006 | B16: 347.83 | C16: 349.91 | D16: 343.68 | E16: 349.25 | F16: 348.53 | G16: 46966300 | J16: 45999 | K16: 69.84 | L16: 70.69 | M16: 68.79 | N16: 70.52 | O16: 70.52 | P16: 102143800
A17: 45999 | B17: 329.88 | C17: 349.84 | D17: 324.71 | E17: 347.83 | F17: 347.11 | G17: 35748200 | J17: 45992 | K17: 0.51 Dividend
A18: 45992 | B18: 332.94 | C18: 334.11 | D18: 324.28 | E18: 331.24 | F18: 330.56 | G18: 33125000 | J18: 45992 | K18: 72.6 | L18: 72.91 | M18: 69.87 | N18: 70 | O18: 69.51 | P18: 82949300
A19: 45985 | B19: 329.24 | C19: 336.06 | D19: 326 | E19: 334.44 | F19: 333.75 | G19: 24087500 | J19: 45985 | K19: 73.16 | L19: 73.23 | M19: 71.57 | N19: 73.12 | O19: 72.61 | P19: 76487900
A20: 45978 | B20: 331.16 | C20: 333.36 | D20: 318 | E20: 327.98 | F20: 327.31 | G20: 38172200 | J20: 45978 | K20: 71.2 | L20: 73.19 | M20: 70.57 | N20: 72.95 | O20: 72.44 | P20: 81901700
A21: 45973 | B21: 0.67 Dividend | J21: 45971 | K21: 70.01 | L21: 71.89 | M21: 69.44 | N21: 71.16 | O21: 70.66 | P21: 72265600
A22: 45971 | B22: 336.65 | C22: 344.26 | D22: 329.03 | E22: 330.02 | F22: 328.69 | G22: 27522700 | J22: 45964 | K22: 68.8 | L22: 70.87 | M22: 67.66 | N22: 70.55 | O22: 70.06 | P22: 82269300
A23: 45964 | B23: 341 | C23: 342.11 | D23: 333.71 | E23: 336.02 | F23: 334.67 | G23: 30269100 | J23: 45957 | K23: 69.78 | L23: 70.9 | M23: 67.9 | N23: 68.9 | O23: 68.42 | P23: 77814500
A24: 45957 | B24: 349 | C24: 350.98 | D24: 338.17 | E24: 340.74 | F24: 339.37 | G24: 34920800 | J24: 45950 | K24: 68.43 | L24: 71.62 | M24: 67.92 | N24: 69.71 | O24: 69.22 | P24: 99408700
A25: 45950 | B25: 341.9 | C25: 349.65 | D25: 338.94 | E25: 347.38 | F25: 345.98 | G25: 24655100 | J25: 45943 | K25: 66.23 | L25: 68.5 | M25: 66 | N25: 68.44 | O25: 67.96 | P25: 70378300
A26: 45943 | B26: 343.72 | C26: 350.08 | D26: 334.17 | E26: 341.89 | F26: 340.51 | G26: 26048500 | J26: 45936 | K26: 66.49 | L26: 67.4 | M26: 65.84 | N26: 67.04 | O26: 66.57 | P26: 70965200
A27: 45936 | B27: 350.01 | C27: 355 | D27: 343.25 | E27: 343.65 | F27: 342.26 | G27: 24438700 | J27: 45929 | K27: 65.67 | L27: 66.99 | M27: 65.35 | N27: 66.65 | O27: 66.19 | P27: 70110900
A28: 45929 | B28: 337.38 | C28: 353.16 | D28: 335.55 | E28: 349.84 | F28: 348.43 | G28: 34160900 | J28: 45922 | K28: 66.16 | L28: 66.92 | M28: 65.5 | N28: 65.67 | O28: 65.21 | P28: 75347400
A29: 45922 | B29: 339.01 | C29: 345.26 | D29: 334.51 | E29: 337.37 | F29: 336.01 | G29: 35989800 | J29: 45915 | K29: 0.51 Dividend
A30: 45915 | B30: 340.61 | C30: 346.2 | D30: 333.47 | E30: 341.61 | F30: 340.23 | G30: 36859600 | J30: 45915 | K30: 66.68 | L30: 67.13 | M30: 66.05 | N30: 66.43 | O30: 65.46 | P30: 100830100
A31: 45908 | B31: 342.34 | C31: 346.32 | D31: 336.44 | E31: 339.43 | F31: 338.06 | G31: 24591600 | J31: 45908 | K31: 67.86 | L31: 68.17 | M31: 66.94 | N31: 67.01 | O31: 66.04 | P31: 85675300
A32: 45901 | B32: 349.31 | C32: 352.63 | D32: 340.2 | E32: 343.22 | F32: 341.84 | G32: 18889000 | J32: 45901 | K32: 68.96 | L32: 69.46 | M32: 67.37 | N32: 67.96 | O32: 66.97 | P32: 99065600
A33: 45894 | B33: 349.61 | C33: 353.43 | D33: 347.45 | E33: 351.78 | F33: 350.36 | G33: 28086100 | J33: 45894 | K33: 70.11 | L33: 70.23 | M33: 68.28 | N33: 68.99 | O33: 67.99 | P33: 73972500
A34: 45887 | B34: 343.84 | C34: 351.2 | D34: 339.72 | E34: 350.04 | F34: 348.63 | G34: 25338000 | J34: 45887 | K34: 69.98 | L34: 71.71 | M34: 69.05 | N34: 70.13 | O34: 69.11 | P34: 67327900
A35: 45881 | B35: 0.59 Dividend | J35: 45880 | K35: 70.3 | L35: 71.06 | M35: 69.39 | N35: 69.92 | O35: 68.9 | P35: 55430500
A36: 45880 | B36: 336.73 | C36: 348.36 | D36: 334.51 | E36: 344.47 | F36: 342.48 | G36: 28262600 | J36: 45873 | K36: 68.72 | L36: 70.87 | M36: 68.31 | N36: 70.34 | O36: 69.32 | P36: 58501400
A37: 45873 | B37: 341.7 | C37: 344.38 | D37: 328.7 | E37: 336.78 | F37: 334.83 | G37: 35446000 | J37: 45866 | K37: 68.74 | L37: 69.42 | M37: 67.74 | N37: 68.86 | O37: 67.86 | P37: 73641300
A38: 45866 | B38: 356.38 | C38: 358.32 | D38: 338.1 | E38: 339.35 | F38: 337.39 | G38: 40753400 | J38: 45859 | K38: 70.19 | L38: 70.62 | M38: 68.6 | N38: 69.17 | O38: 68.16 | P38: 86267800
A39: 45859 | B39: 349.06 | C39: 357.65 | D39: 348.4 | E39: 357.04 | F39: 354.98 | G39: 24018700 | J39: 45852 | K39: 69.8 | L39: 70.7 | M39: 68.79 | N39: 69.85 | O39: 68.83 | P39: 75194000
A40: 45852 | B40: 347.39 | C40: 351.97 | D40: 345.01 | E40: 349.05 | F40: 347.03 | G40: 25709500 | J40: 45845 | K40: 71.37 | L40: 71.37 | M40: 68.97 | N40: 69.87 | O40: 68.85 | P40: 95329400
...

Sheet Analysis
A1: Date | B1: V | C1: KO | F1: Weekly return for V | G1: Weekly return for KO | J1: Statistics | N1: Сoefficients
A2: 46091 | B2: =VLOOKUP(A2,Data!A:G,6,0) -> 316.11 | C2: =VLOOKUP(A2,Data!J:P,6,0) -> 78.13 | F2: =(B2-B3)/B3 -> 0.00044308004 | G2: =(C2-C3)/C3 -> 0.0042416452 | K2: V | L2: KO | O2: V | P2: KO
A3: 46090 | B3: =VLOOKUP(A3,Data!A:G,6,0) -> 315.97 | C3: =VLOOKUP(A3,Data!J:P,6,0) -> 77.8 | F3: =(B3-B4)/B4 -> -0.004379884 | G3: =(C3-C4)/C4 -> 0.0098650052 | J3: Max | K3: =MAX(F2:F54) -> 0.064736165 | L3: =MAX(G2:G54) -> 0.056409571 | N3: Risk-free rate | O3: =0.02/52 -> 0.00038461538 | P3: =0.02/52 -> 0.00038461538
A4: 46083 | B4: =VLOOKUP(A4,Data!A:G,6,0) -> 317.36 | C4: =VLOOKUP(A4,Data!J:P,6,0) -> 77.04 | F4: =(B4-B5)/B5 -> -0.0086837009 | G4: =(C4-C5)/C5 -> -0.055419323 | J4: Min | K4: =MIN(F2:F54) -> -0.086688216 | L4: =MIN(G2:G54) -> -0.055419323 | N4: Sharpe ratio | O4: =(K11-O3)/K14 -> -0.025222952 | P4: =(K11-P3)/L14 -> -0.039286465
A5: 46076 | B5: =VLOOKUP(A5,Data!A:G,6,0) -> 320.14 | C5: =VLOOKUP(A5,Data!J:P,6,0) -> 81.56 | F5: =(B5-B6)/B6 -> -0.0025237576 | G5: =(C5-C6)/C6 -> 0.021543086 | J5: Range: | K5: =K3-K4 -> 0.15142438 | L5: =L3-L4 -> 0.11182889 | N5: Zmax | O5: =(K3-K11)/K14 -> 2.2313375 | P5: =(L3-L11)/L14 -> 2.7923666
A6: 46069 | B6: =VLOOKUP(A6,Data!A:G,6,0) -> 320.95 | C6: =VLOOKUP(A6,Data!J:P,6,0) -> 79.84 | F6: =(B6-B7)/B7 -> 0.023992598 | G6: =(C6-C7)/C7 -> 0.014743264 | N6: Zmin | O6: =(K4-K11)/K14 -> -2.9598278 | P6: =(L4-L11)/L14 -> -3.1789506
A7: 46062 | B7: =VLOOKUP(A7,Data!A:G,6,0) -> 313.43 | C7: =VLOOKUP(A7,Data!J:P,6,0) -> 78.68 | F7: =(B7-B8)/B8 -> -0.052795406 | G7: =(C7-C8)/C8 -> -0.004428698 | J7: Q3 | K7: =PERCENTILE(F3:F55, 0.75) -> 0.020106774 | L7: =PERCENTILE(G3:G55, 0.75) -> 0.02091383
A8: 46055 | B8: =VLOOKUP(A8,Data!A:G,6,0) -> 330.9 | C8: =VLOOKUP(A8,Data!J:P,6,0) -> 79.03 | F8: =(B8-B9)/B9 -> 0.030295482 | G8: =(C8-C9)/C9 -> 0.056409571 | J8: Q1 | K8: =PERCENTILE(F4:F56, 0.25) -> -0.015778598 | L8: =PERCENTILE(G4:G56, 0.25) -> -0.0081285499
A9: 46048 | B9: =VLOOKUP(A9,Data!A:G,6,0) -> 321.17 | C9: =VLOOKUP(A9,Data!J:P,6,0) -> 74.81 | F9: =(B9-B10)/B10 -> -0.013332924 | G9: =(C9-C10)/C10 -> 0.026481888 | J9: IQR | K9: =K7-K8 -> 0.035885372 | L9: =L7-L8 -> 0.02904238
A10: 46041 | B10: =VLOOKUP(A10,Data!A:G,6,0) -> 325.51 | C10: =VLOOKUP(A10,Data!J:P,6,0) -> 72.88 | F10: =(B10-B11)/B11 -> -0.0064403883 | G10: =(C10-C11)/C11 -> 0.034639409
A11: 46034 | B11: =VLOOKUP(A11,Data!A:G,6,0) -> 327.62 | C11: =VLOOKUP(A11,Data!J:P,6,0) -> 70.44 | F11: =(B11-B12)/B12 -> -0.061395216 | G11: =(C11-C12)/C12 -> -0.00099276698 | J11: Mean | K11: =AVERAGE(F2:F54) -> -0.00035112882 | L11: =AVERAGE(G2:G55) -> 0.004115034
A12: 46027 | B12: =VLOOKUP(A12,Data!A:G,6,0) -> 349.05 | C12: =VLOOKUP(A12,Data!J:P,6,0) -> 70.51 | F12: =(B12-B13)/B13 -> 0.0094860746 | G12: =(C12-C13)/C13 -> 0.020109954 | J12: Mean Absolute Deviation | K12: =AVEDEV(F2:F55) -> 0.02274534 | L12: =AVEDEV(G2:G55) -> 0.014804505
A13: 46020 | B13: =VLOOKUP(A13,Data!A:G,6,0) -> 345.77 | C13: =VLOOKUP(A13,Data!J:P,6,0) -> 69.12 | F13: =(B13-B14)/B14 -> -0.023993 | G13: =(C13-C14)/C14 -> -0.010734221 | J13: Variance | K13: =_xlfn.VAR.S(F2:F55) -> 0.00085086741 | L13: =_xlfn.VAR.S(G2:G55) -> 0.00035072586
A14: 46013 | B14: =VLOOKUP(A14,Data!A:G,6,0) -> 354.27 | C14: =VLOOKUP(A14,Data!J:P,6,0) -> 69.87 | F14: =(B14-B15)/B15 -> 0.016469171 | G14: =(C14-C15)/C15 -> -0.0027119612 | J14: Standard Deviation | K14: =_xlfn.STDEV.S(F2:F55) -> 0.029169632 | L14: =_xlfn.STDEV.S(G2:G55) -> 0.018727676
A15: 46006 | B15: =VLOOKUP(A15,Data!A:G,6,0) -> 348.53 | C15: =VLOOKUP(A15,Data!J:P,6,0) -> 70.06 | F15: =(B15-B16)/B16 -> 0.0040909222 | G15: =(C15-C16)/C16 -> -0.0065229722 | J15: CV | K15: =ABS(K14/K11) -> 83.073875 | L15: =L14/L11 -> 4.5510381
A16: 45999 | B16: =VLOOKUP(A16,Data!A:G,6,0) -> 347.11 | C16: =VLOOKUP(A16,Data!J:P,6,0) -> 70.52 | F16: =(B16-B17)/B17 -> 0.050066554
A17: 45992 | B17: =VLOOKUP(A17,Data!A:G,6,0) -> 330.56 | C17: =VLOOKUP(A17,Data!J:P,6,0) | F17: =(B17-B18)/B18 -> -0.0095580524
A18: 45985 | B18: =VLOOKUP(A18,Data!A:G,6,0) -> 333.75 | C18: =VLOOKUP(A18,Data!J:P,6,0) -> 72.61 | F18: =(B18-B19)/B19 -> 0.019675537 | G18: =(C18-C19)/C19 -> 0.0023467697
A19: 45978 | B19: =VLOOKUP(A19,Data!A:G,6,0) -> 327.31 | C19: =VLOOKUP(A19,Data!J:P,6,0) -> 72.44 | F19: =(B19-B20)/B20 -> -0.0041984849 | G19: =(C19-C20)/C20 -> 0.025191056
A20: 45971 | B20: =VLOOKUP(A20,Data!A:G,6,0) -> 328.69 | C20: =VLOOKUP(A20,Data!J:P,6,0) -> 70.66 | F20: =(B20-B21)/B21 -> -0.017868348 | G20: =(C20-C21)/C21 -> 0.0085640879
A21: 45964 | B21: =VLOOKUP(A21,Data!A:G,6,0) -> 334.67 | C21: =VLOOKUP(A21,Data!J:P,6,0) -> 70.06 | F21: =(B21-B22)/B22 -> -0.013849191 | G21: =(C21-C22)/C22 -> 0.0239696
A22: 45957 | B22: =VLOOKUP(A22,Data!A:G,6,0) -> 339.37 | C22: =VLOOKUP(A22,Data!J:P,6,0) -> 68.42 | F22: =(B22-B23)/B23 -> -0.019105151 | G22: =(C22-C23)/C23 -> -0.011557353
A23: 45950 | B23: =VLOOKUP(A23,Data!A:G,6,0) -> 345.98 | C23: =VLOOKUP(A23,Data!J:P,6,0) -> 69.22 | F23: =(B23-B24)/B24 -> 0.016064139 | G23: =(C23-C24)/C24 -> 0.018540318
A24: 45943 | B24: =VLOOKUP(A24,Data!A:G,6,0) -> 340.51 | C24: =VLOOKUP(A24,Data!J:P,6,0) -> 67.96 | F24: =(B24-B25)/B25 -> -0.0051130719 | G24: =(C24-C25)/C25 -> 0.020880276
A25: 45936 | B25: =VLOOKUP(A25,Data!A:G,6,0) -> 342.26 | C25: =VLOOKUP(A25,Data!J:P,6,0) -> 66.57 | F25: =(B25-B26)/B26 -> -0.017708004 | G25: =(C25-C26)/C26 -> 0.0057410485
A26: 45929 | B26: =VLOOKUP(A26,Data!A:G,6,0) -> 348.43 | C26: =VLOOKUP(A26,Data!J:P,6,0) -> 66.19 | F26: =(B26-B27)/B27 -> 0.036963186 | G26: =(C26-C27)/C27 -> 0.01502837
A27: 45922 | B27: =VLOOKUP(A27,Data!A:G,6,0) -> 336.01 | C27: =VLOOKUP(A27,Data!J:P,6,0) -> 65.21 | F27: =(B27-B28)/B28 -> -0.012403374
A28: 45915 | B28: =VLOOKUP(A28,Data!A:G,6,0) -> 340.23 | C28: =VLOOKUP(A28,Data!J:P,6,0) | F28: =(B28-B29)/B29 -> 0.0064189789
A29: 45908 | B29: =VLOOKUP(A29,Data!A:G,6,0) -> 338.06 | C29: =VLOOKUP(A29,Data!J:P,6,0) -> 66.04 | F29: =(B29-B30)/B30 -> -0.011057805 | G29: =(C29-C30)/C30 -> -0.013886815
A30: 45901 | B30: =VLOOKUP(A30,Data!A:G,6,0) -> 341.84 | C30: =VLOOKUP(A30,Data!J:P,6,0) -> 66.97 | F30: =(B30-B31)/B31 -> -0.024317845 | G30: =(C30-C31)/C31 -> -0.015002206
A31: 45894 | B31: =VLOOKUP(A31,Data!A:G,6,0) -> 350.36 | C31: =VLOOKUP(A31,Data!J:P,6,0) -> 67.99 | F31: =(B31-B32)/B32 -> 0.0049622809 | G31: =(C31-C32)/C32 -> -0.016206048
A32: 45887 | B32: =VLOOKUP(A32,Data!A:G,6,0) -> 348.63 | C32: =VLOOKUP(A32,Data!J:P,6,0) -> 69.11 | F32: =(B32-B33)/B33 -> 0.017957253 | G32: =(C32-C33)/C33 -> 0.0030478955
A33: 45880 | B33: =VLOOKUP(A33,Data!A:G,6,0) -> 342.48 | C33: =VLOOKUP(A33,Data!J:P,6,0) -> 68.9 | F33: =(B33-B34)/B34 -> 0.022847415 | G33: =(C33-C34)/C34 -> -0.0060588575
A34: 45873 | B34: =VLOOKUP(A34,Data!A:G,6,0) -> 334.83 | C34: =VLOOKUP(A34,Data!J:P,6,0) -> 69.32 | F34: =(B34-B35)/B35 -> -0.0075876582 | G34: =(C34-C35)/C35 -> 0.021514884
A35: 45866 | B35: =VLOOKUP(A35,Data!A:G,6,0) -> 337.39 | C35: =VLOOKUP(A35,Data!J:P,6,0) -> 67.86 | F35: =(B35-B36)/B36 -> -0.049552087 | G35: =(C35-C36)/C36 -> -0.0044014085
A36: 45859 | B36: =VLOOKUP(A36,Data!A:G,6,0) -> 354.98 | C36: =VLOOKUP(A36,Data!J:P,6,0) -> 68.16 | F36: =(B36-B37)/B37 -> 0.022908682 | G36: =(C36-C37)/C37 -> -0.0097341276
A37: 45852 | B37: =VLOOKUP(A37,Data!A:G,6,0) -> 347.03 | C37: =VLOOKUP(A37,Data!J:P,6,0) -> 68.83 | F37: =(B37-B38)/B38 -> 0.0032088344 | G37: =(C37-C38)/C38 -> -0.00029048656
A38: 45845 | B38: =VLOOKUP(A38,Data!A:G,6,0) -> 345.92 | C38: =VLOOKUP(A38,Data!J:P,6,0) -> 68.85 | F38: =(B38-B39)/B39 -> -0.030466101 | G38: =(C38-C39)/C39 -> -0.020765183
A39: 45838 | B39: =VLOOKUP(A39,Data!A:G,6,0) -> 356.79 | C39: =VLOOKUP(A39,Data!J:P,6,0) -> 70.31 | F39: =(B39-B40)/B40 -> 0.029399885 | G39: =(C39-C40)/C40 -> 0.014427932
A40: 45831 | B40: =VLOOKUP(A40,Data!A:G,6,0) -> 346.6 | C40: =VLOOKUP(A40,Data!J:P,6,0) -> 69.31 | F40: =(B40-B41)/B41 -> 0.029678263 | G40: =(C40-C41)/C41 -> 0.021668632
...

Sheet Regression
A1: Date | B1: V | C1: KO
A2: 46091 | B2: 0.00044308004 | C2: 0.0042416452 | F2: SUMMARY OUTPUT
A3: 46090 | B3: -0.004379884 | C3: 0.0098650052
A4: 46083 | B4: -0.0086837009 | C4: -0.055419323 | F4: Regression Statistics
A5: 46076 | B5: -0.0025237576 | C5: 0.021543086 | F5: Multiple R | G5: 0,321993
A6: 46069 | B6: 0.023992598 | C6: 0.014743264 | F6: R Square | G6: 0,10368
A7: 46062 | B7: -0.052795406 | C7: -0.004428698 | F7: Adjusted R Square | G7: 0,084609
A8: 46055 | B8: 0.030295482 | C8: 0.056409571 | F8: Standard Error | G8: 0,028106
A9: 46048 | B9: -0.013332924 | C9: 0.026481888 | F9: Observations | G9: 49
A10: 46041 | B10: -0.0064403883 | C10: 0.034639409
A11: 46034 | B11: -0.061395216 | C11: -0.00099276698 | F11: ANOVA
A12: 46027 | B12: 0.0094860746 | C12: 0.020109954 | G12: df | H12: SS | I12: MS | J12: F | K12: Significance F
A13: 46020 | B13: -0.023993 | C13: -0.010734221 | F13: Regression | G13: 1 | H13: 0,004295 | I13: 0,004295 | J13: 5,436604 | K13: 0,024056
A14: 46013 | B14: 0.016469171 | C14: -0.0027119612 | F14: Residual | G14: 47 | H14: 0,037127 | I14: 0,00079
A15: 46006 | B15: 0.0040909222 | C15: -0.0065229722 | F15: Total | G15: 48 | H15: 0,041422
A16: 45999 | B16: 0.050066554
A17: 45992 | B17: -0.0095580524 | G17: Coefficients | H17: Standard Error | I17: t Stat | J17: P-value | K17: Lower 95% | L17: Upper 95% | M17: Lower 95,0% | N17: Upper 95,0%
A18: 45985 | B18: 0.019675537 | C18: 0.0023467697 | F18: Intercept | G18: -0,00316 | H18: 0,004113 | I18: -0,76903 | J18: 0,445725 | K18: -0,01144 | L18: 0,005111 | M18: -0,01144 | N18: 0,005111
A19: 45978 | B19: -0.0041984849 | C19: 0.025191056 | F19: KO | G19: 0,504919 | H19: 0,21655 | I19: 2,331653 | J19: 0,024056 | K19: 0,069277 | L19: 0,940561 | M19: 0,069277 | N19: 0,940561
A20: 45971 | B20: -0.017868348 | C20: 0.0085640879
A21: 45964 | B21: -0.013849191 | C21: 0.0239696
A22: 45957 | B22: -0.019105151 | C22: -0.011557353
A23: 45950 | B23: 0.016064139 | C23: 0.018540318 | G23: Correlation | H23: Covariance | J23: CAPM Regression
A24: 45943 | B24: -0.0051130719 | C24: 0.020880276 | F24: V - KO | G24: =correl(B2:B54, C2:C54) -> 0.32574013 | H24: =_xlfn.COVARIANCE.S(B2:B54, C2:C54) -> 0.00017915946 | J24: Alpha | K24: =G18 -> -0,00316
A25: 45936 | B25: -0.017708004 | C25: 0.0057410485 | J25: Beta | K25: =G19 -> 0,504919
A26: 45929 | B26: 0.036963186 | C26: 0.01502837 | J26: p-value | K26: =J19 -> 0,024056
A27: 45922 | B27: -0.012403374 | J27: R square | K27: =G6 -> 0,10368
A28: 45915 | B28: 0.0064189789 | J28: F significance | K28: =K13 -> 0,024056
A29: 45908 | B29: -0.011057805 | C29: -0.013886815
A30: 45901 | B30: -0.024317845 | C30: -0.015002206
A31: 45894 | B31: 0.0049622809 | C31: -0.016206048
A32: 45887 | B32: 0.017957253 | C32: 0.0030478955
A33: 45880 | B33: 0.022847415 | C33: -0.0060588575
A34: 45873 | B34: -0.0075876582 | C34: 0.021514884
A35: 45866 | B35: -0.049552087 | C35: -0.0044014085
A36: 45859 | B36: 0.022908682 | C36: -0.0097341276
A37: 45852 | B37: 0.0032088344 | C37: -0.00029048656
A38: 45845 | B38: -0.030466101 | C38: -0.020765183
A39: 45838 | B39: 0.029399885 | C39: 0.014427932
A40: 45831 | B40: 0.029678263 | C40: 0.021668632
...
